Workbook

Sheet לוח בקרה
A1: הכנת שבת — מדרשת עין פרת
A2: צהוב = ממלאים · טורקיז = הסקריפט כותב · אפור = מחושב
A4: שבת | B4: =IF('לוז'!B3="","— בחר תאריך ב«לוז» —",'לוז'!B3) | E4: סדר העבודה
A5: כניסת שבת | B5: ='לוז'!B4 | D5: 1 | E5: «לוז» — בוחרים תאריך, מתקנים שעות ומקומות. «הצעה» מתעדכנת לבד; «שעה» היא מה שנשלח.
A6: צאת שבת | B6: ='לוז'!D4 | D6: 2 | E6: «משימות» — לכל משימה: שלב, יום, שעה, קבוצה, כמה אנשים, מתכון (לצוות הכנה), ניקוד ועוגן בלו"ז.
D7: 3 | E7: python3 tools/assign_groups.py <תאריך> — ממלא «שמות», «קבוצות», «חניכים» ו«היסטוריה».
A8: מצב ההכנה | C8: הערה | D8: 4 | E8: python3 tools/export_pdf.py <תאריך> — לו"ז צל + פלייר לכל קבוצת עבודה. ערכת בשיטס? הורד כ-xlsx והרץ שוב.
A9: נוכחים השבת | B9: =COUNTIF('חניכים'!$D$3:$D$132,"כן")+COUNTIF('חניכים'!$D$3:$D$132,"לא") | C9: מתוך רשימת הנוכחות
A10: זמינים לתורנות | B10: =COUNTIF('חניכים'!$D$3:$D$132,"כן")
A11: בתורנות | B11: =COUNTA('חניכים'!$E$3:$E$132) | C11: חניכים עם קבוצה אחת לפחות | E11: איך זה עובד
A12: זמינים בלי תורנות | B12: =COUNTIFS('חניכים'!$D$3:$D$132,"כן",'חניכים'!$E$3:$E$132,"") | D12: • | E12: שלבים: הכנות שישי (בוקר) · תורנות שישי (צהריים–אחה"צ) · תורנות שבת (ערב ושבת). חניך יכול להיות בקבוצה אחת בכל שלב.
A13: משימות | B13: =COUNTA('משימות'!$E$3:$E$122) | D13: • | E13: גודל קבוצה = שיא האנשים שנדרשים בו-זמנית במשימות שלה. משימה בלי שעה = כל הקבוצה. משימה בלי קבוצה = בלו"ז הצל בלי שמות.
A14: משימות בלי שמות | B14: =COUNTA('משימות'!$E$3:$E$122)-COUNTA('משימות'!$G$3:$G$122) | C14: להריץ שיבוץ, או להשלים ידנית | D14: • | E14: עוגן = האירוע בלו"ז שלידו המשימה מופיעה בלו"ז הצל. הרשימה הנגללת נלקחת מעמודת «אירוע» ב«לוז».
A15: משימות בלי עוגן | B15: =COUNTA('משימות'!$E$3:$E$122)-COUNTA('משימות'!$I$3:$I$122) | C15: לא יופיעו ליד אירוע בלו"ז הצל | D15: • | E15: «ניקוד» במשימה (1 רגיל, 2 קשה, 3 קשה מאוד) נצבר ל«חניכים» ול«היסטוריה» — מי שצבר פחות משובץ קודם.
A16: קבוצות עבודה | B16: =COUNTA('קבוצות'!$A$3:$A$32) | C16: פלייר לכל אחת | D16: • | E16: מתכון על הפלייר: ב«משימות» בוחרים מנה בעמודת «מתכון», והמתכון מ«מתכונים» מודפס בפלייר של הקבוצה.

Sheet לוז
A1: לו"ז השבת
A3: תאריך השבת | B3: 46283 | C3: פרשה | D3: =IFERROR(VLOOKUP($B$3,'זמנים'!$A$3:$D$400,2,FALSE),"") | E3: בחר תאריך מהרשימה — כניסה, צאה ופרשה נטענות מ«זמנים»
A4: כניסת שבת | B4: =IFERROR(VLOOKUP($B$3,'זמנים'!$A$3:$D$400,3,FALSE),"") | C4: צאת שבת | D4: =IFERROR(VLOOKUP($B$3,'זמנים'!$A$3:$D$400,4,FALSE),"")
A6: יום | B6: שעה | C6: אירוע | D6: מקום | E6: הערה | F6: הצעה | G6: משימות
A7: שישי | B7: 0.33333333 | C7: תחילת עבודה | F7: 0.33333333 | G7: =IF(C7="","",COUNTIF('משימות'!$I$3:$I$122,C7))
A8: שישי | B8: 0.5 | C8: ארוחת צהריים | F8: 0.5 | G8: =IF(C8="","",COUNTIF('משימות'!$I$3:$I$122,C8))
A9: שישי | B9: 0.75138889 | C9: הדלקת נרות | F9: =IF($B$4="","",$B$4) | G9: =IF(C9="","",COUNTIF('משימות'!$I$3:$I$122,C9))
A10: שישי | B10: 0.75694444 | C10: קבלת שבת וערבית | D10: בית מיכאל | F10: =IF($B$4="","",ROUND(($B$4+TIME(0,10,0))*288,0)/288) | G10: =IF(C10="","",COUNTIF('משימות'!$I$3:$I$122,C10))
A11: שישי | B11: 0.81944444 | C11: סעודת שבת | D11: חדר אוכל | F11: =IF($B$4="","",ROUND(($B$4+TIME(1,40,0))*288,0)/288) | G11: =IF(C11="","",COUNTIF('משימות'!$I$3:$I$122,C11))
A12: שישי | B12: 0.88194444 | C12: טיש בחדר אוכל | D12: חדר אוכל | F12: =IF($B$4="","",ROUND(($B$4+TIME(3,10,0))*288,0)/288) | G12: =IF(C12="","",COUNTIF('משימות'!$I$3:$I$122,C12))
A13: שבת | B13: 0.45833333 | C13: קידוש | F13: 0.45833333 | G13: =IF(C13="","",COUNTIF('משימות'!$I$3:$I$122,C13))
A14: שבת | B14: 0.48958333 | C14: חבורות | F14: 0.48958333 | G14: =IF(C14="","",COUNTIF('משימות'!$I$3:$I$122,C14))
A15: שבת | B15: 0.55208333 | C15: ארוחת צהריים | D15: חדר אוכל | F15: 0.55208333 | G15: =IF(C15="","",COUNTIF('משימות'!$I$3:$I$122,C15))
A16: שבת | B16: 0.70833333 | C16: שיעור | F16: 0.70833333 | G16: =IF(C16="","",COUNTIF('משימות'!$I$3:$I$122,C16))
A17: שבת | B17: 0.73611111 | C17: סעודה שלישית | F17: =IF($D$4="","",ROUND(($D$4-TIME(1,40,0))*288,0)/288) | G17: =IF(C17="","",COUNTIF('משימות'!$I$3:$I$122,C17))
A18: שבת | B18: 0.80555556 | C18: הבדלה | F18: =IF($D$4="","",$D$4) | G18: =IF(C18="","",COUNTIF('משימות'!$I$3:$I$122,C18))
A19: שבת | B19: 0.81944444 | C19: ניקיונות מוצ"ש | D19: בית המדרש | F19: =IF($D$4="","",ROUND(($D$4+TIME(0,20,0))*288,0)/288) | G19: =IF(C19="","",COUNTIF('משימות'!$I$3:$I$122,C19))
G20: =IF(C20="","",COUNTIF('משימות'!$I$3:$I$122,C20))
G21: =IF(C21="","",COUNTIF('משימות'!$I$3:$I$122,C21))
G22: =IF(C22="","",COUNTIF('משימות'!$I$3:$I$122,C22))
G23: =IF(C23="","",COUNTIF('משימות'!$I$3:$I$122,C23))
G24: =IF(C24="","",COUNTIF('משימות'!$I$3:$I$122,C24))
G25: =IF(C25="","",COUNTIF('משימות'!$I$3:$I$122,C25))
G26: =IF(C26="","",COUNTIF('משימות'!$I$3:$I$122,C26))
G27: =IF(C27="","",COUNTIF('משימות'!$I$3:$I$122,C27))
G28: =IF(C28="","",COUNTIF('משימות'!$I$3:$I$122,C28))
G29: =IF(C29="","",COUNTIF('משימות'!$I$3:$I$122,C29))
G30: =IF(C30="","",COUNTIF('משימות'!$I$3:$I$122,C30))
G31: =IF(C31="","",COUNTIF('משימות'!$I$3:$I$122,C31))
... G36: =IF(C36="","",COUNTIF('משימות'!$I$3:$I$122,C36))
A38: «שעה» היא הלו"ז שנשלח בפועל — עורכים בה חופשי. «הצעה» מחושבת מכניסת/צאת השבת (הכללים ב-data/schedule_template.csv). «משימות» = כמה משימות מעוגנות לאירוע בלו"ז הצל.

Sheet משימות
A1: משימות השבת — מי עושה מה ומתי
A2: שלב | B2: יום | C2: שעה | D2: קבוצה | E2: משימה | F2: אנשים | G2: שמות | H2: מתכון | I2: עוגן בלו"ז | J2: הערה
A3: הכנות שישי | B3: שישי | C3: 0.33333333 | D3: חלות | E3: לישה, התפחה, קליעה ואפייה | F3: 5 | G3: איתמר אסנהיים, איתן כהן, נועם ישראל קומפאס, תמר פרימור, יהב לוי | H3: חלות | I3: תחילת עבודה | J3: בסיום — לרשום «שנה ב'» על הנייר כסף / השקית
A4: הכנות שישי | B4: שישי | C4: 0.33333333 | D4: עוגות שמרים | E4: בצק, מילוי, קליעת קראנץ' ואפייה | F4: 4 | G4: חיים שמאי, טליה קור, ניצן שטיין, של״ו רובינשטיין | H4: עוגות שמרים (קראנץ' קינמון ושוקולד) | I4: תחילת עבודה | J4: בסיום — לרשום «שנה ב'» על הנייר כסף / השקית
A5: הכנות שישי | B5: שישי | C5: 0.33333333 | D5: מטבוחה | E5: בישול ארוך עד מרקם ריבתי | F5: 4 | G5: הלל פינגולד, אביב רוזנטל, נגה חוה כהן, אורי טילינגר | H5: מטבוחה | I5: תחילת עבודה | J5: בסיום — לרשום «שנה ב'» על הנייר כסף / השקית
A6: הכנות שישי | B6: שישי | C6: 0.33333333 | D6: עוגת דבש | E6: אפיית 10–12 תבניות אינגליש | F6: 2 | G6: איתי בן מנחם, משה אוברשטיין | H6: עוגת דבש | I6: תחילת עבודה | J6: בסיום — לרשום «שנה ב'» על הנייר כסף / השקית
A7: הכנות שישי | B7: שישי | C7: 0.33333333 | D7: עוגיות שוקולד צ'יפס | E7: הכנת הבצק, כדרור ואפייה | F7: 2 | G7: הילי אלפסי, נבו בלוך | H7: עוגיות שוקולד צ'יפס | I7: תחילת עבודה | J7: בסיום — לרשום «שנה ב'» על הנייר כסף / השקית
A8: הכנות שישי | B8: שישי | C8: 0.33333333 | D8: בראוניז ללא גלוטן | E8: המסה, ערבוב ואפייה | F8: 2 | G8: יובל רוזנברג, ארבל פרנקו | H8: בראוניז ללא גלוטן | I8: תחילת עבודה | J8: בסיום — לרשום «שנה ב'» על הנייר כסף / השקית
A9: הכנות שישי | B9: שישי | C9: 0.33333333 | D9: סלט חצילים | E9: קלייה, סינון, קיצוץ ותיבול | F9: 2 | G9: יובל יצחק, רוני כהן | H9: סלט חצילים קלויים | I9: תחילת עבודה | J9: בסיום — לרשום «שנה ב'» על הנייר כסף / השקית
A10: הכנות שישי | B10: שישי | C10: 0.33333333 | D10: ארוחת צהריים שישי | E10: הכנת החומוס | F10: 2 | G10: איתי גוסטינר, שירה אדלה לוזון | I10: תחילת עבודה | J10: בסיום — לרשום «שנה ב'» על הנייר כסף / השקית
A11: הכנות שישי | B11: שישי | C11: 0.5 | D11: ארוחת צהריים שישי | E11: הגשת ארוחת הצהריים | F11: 2 | G11: איתי גוסטינר, שירה אדלה לוזון | I11: ארוחת צהריים
A12: הכנות שישי | B12: שישי | C12: 0.54166667 | D12: ארוחת צהריים שישי | E12: קיפול הארוחה, שטיפת כלים | F12: 2 | G12: איתי גוסטינר, שירה אדלה לוזון | I12: ארוחת צהריים
A13: תורנות שישי | B13: שישי | C13: 0.33333333 | D13: בית מדרש | E13: העברת שולחנות לכיתת בית המדרש — לא בגרירה | F13: 6 | G13: אלרואי גרינברג, עומר יוסף גנון, תמר פרידמן, רועי צבי סרי, פרת פולס, ליבי בוכריס | I13: תחילת עבודה
A14: תורנות שישי | B14: שישי | C14: 0.33333333 | D14: בית מדרש | E14: טאטוא ושטיפת רצפה | F14: 3 | G14: ניצן גמלא, אלה מאיר, עשהאל ירושלמי | I14: תחילת עבודה
A15: תורנות שישי | B15: שישי | C15: 0.33333333 | D15: בית מדרש | E15: תליית מחיצה | F15: 2 | G15: איתי רוס, עופר בביוף | I15: תחילת עבודה
A16: תורנות שישי | B16: שישי | C16: 0.33333333 | D16: בית מדרש | E16: סידור כסאות בשורות — כולל 3 שורות עזרת ישראל | F16: 4 | G16: איתי בן יהודה, הילה לביא, אנה עזריאל, ירדן בן שחר | I16: תחילת עבודה
A17: תורנות שישי | B17: שישי | C17: 0.33333333 | D17: בית מדרש | E17: הנחת סידורים על הכסאות | F17: 1 | G17: שליו שישו | I17: תחילת עבודה
A18: תורנות שישי | B18: שישי | C18: 0.41666667 | D18: בית מדרש | E18: עזרה בהכנת החלות | F18: 8 | G18: אלרואי גרינברג, עומר יוסף גנון, תמר פרידמן, רועי צבי סרי, פרת פולס, ליבי בוכריס, ניצן גמלא, אלה מאיר | I18: תחילת עבודה
A19: תורנות שישי | B19: שישי | C19: 0.41666667 | D19: בית מדרש | E19: עזרה בהכנת עוגות השמרים | F19: 8 | G19: עשהאל ירושלמי, איתי רוס, עופר בביוף, איתי בן יהודה, הילה לביא, אנה עזריאל, ירדן בן שחר, שליו שישו | I19: תחילת עבודה
A20: תורנות שבת | B20: שישי | C20: 0.58333333 | D20: ארוחת ערב | E20: פריקת האוכל למקרר — אוכל ארוחת צהריים שבת: כתף בקר, אורז לבן, תפו"א ובטטה, אנטי פסטי, שווארמה טבעונית | F20: 3 | G20: מישל דוד, איתן וינסטון, זואי כהן | I20: הדלקת נרות | J20: הגסטרונומים המסומנים 2 — שנה ב'
A21: תורנות שבת | B21: שישי | C21: 0.70833333 | D21: ארוחת ערב | E21: הכנסת הגסטרונומים של ארוחת הערב מהמקרר לתנור החימום: פרגית בגריל, קוסקוס, לקט קוסקוס, מוקפץ טבעוני · וחיבור מיחמים בפינת קפה | F21: 3 | G21: שירה ספונוב, אורי אסף, יונתן לירז | I21: הדלקת נרות | J21: הגסטרונומים המסומנים 2 — שנה ב'
A22: תורנות שבת | B22: שישי | C22: 0.8125 | D22: ארוחת ערב | E22: הוצאת הגסטרונומים מתנור החימום | F22: 3 | G22: אלה גוטליב, עמית שי אברהם, מישל דוד | I22: סעודת שבת
A23: תורנות שבת | B23: שישי | C23: 0.8125 | D23: ארוחת ערב | E23: עריכת שולחן: הכנת סלט כרוב וסלט טחינה, סלטי קייטרינג (סלק אדום, ירקות מוחמצים, בטטה, כרוב במיונז, חומוס), חצי מהמטבוחה, חצי מהחלות, צלחות וסכו"ם | F23: 5 | G23: איתן וינסטון, זואי כהן, שירה ספונוב, אורי אסף, יונתן לירז | I23: סעודת שבת
A24: תורנות שבת | B24: שישי | D24: ארוחת ערב | E24: שטיפת הגסטרונומים בסיום הטיש | G24: מישל דוד, איתן וינסטון, זואי כהן, שירה ספונוב, אורי אסף, יונתן לירז, אלה גוטליב, עמית שי אברהם | I24: טיש בחדר אוכל
A25: תורנות שבת | B25: שישי | C25: 0.875 | D25: טיש | E25: חימום העוגות: 7 פסי עוגת דבש, 4 קראנצ'ים וחצי מהבראוניז — הכל פרווה | F25: 2 | G25: מעיין רחל דינר, הדר עמדי | I25: טיש בחדר אוכל
A26: תורנות שבת | B26: שישי | C26: 0.875 | D26: טיש | E26: חיתוך 10 תפוחים | F26: 1 | G26: רגב שהם | I26: טיש בחדר אוכל
A27: תורנות שבת | B27: שישי | C27: 0.89583333 | D27: טיש | E27: פריסת שולחן במרכז: העוגות, גרעינים, חצי מהענבים ו-10 התפוחים | F27: 3 | G27: אחיה נחמני, מעיין יוספי, מעיין רחל דינר | I27: טיש בחדר אוכל
A28: תורנות שבת | B28: שישי | C28: 0.89583333 | D28: טיש | E28: סידור המרחב: שולחנות בקוביה במרכז, כיסאות במעגל מסביב | F28: 2 | G28: הדר עמדי, רגב שהם | I28: טיש בחדר אוכל
A29: תורנות שבת | B29: שישי | D29: טיש | E29: טאטוא חדר האוכל וניקוי השולחנות בסיום הטיש | G29: מעיין רחל דינר, הדר עמדי, רגב שהם, אחיה נחמני, מעיין יוספי | I29: טיש בחדר אוכל
A30: תורנות שבת | B30: שבת | C30: 0.4375 | D30: קידוש | E30: סידור וניקיון פינת קפה — להוציא חלב, למלא קפה וסוכר | F30: 1 | G30: עמרי קולטון | I30: קידוש
A31: תורנות שבת | B31: שבת | C31: 0.4375 | D31: קידוש | E31: חימום העוגות | F31: 1 | G31: ליאור שימרלינג | I31: קידוש
A32: תורנות שבת | B32: שבת | C32: 0.4375 | D32: קידוש | E32: טאטוא הרצפה, סידור כיסאות וארגון המרחב | F32: 1 | G32: יעל ברחד | I32: קידוש
A33: תורנות שבת | B33: שבת | C33: 0.4375 | D33: קידוש | E33: הוצאת העוגות: 4 פסי עוגת דבש, 3 קראנצ'ים, העוגיות וחצי מהבראוניז | F33: 1 | G33: אריאלה מרכוס | I33: קידוש
A34: תורנות שבת | B34: שבת | C34: 0.4375 | D34: קידוש | E34: הוצאת חלב, קורנפלקס וחצי מהענבים | F34: 1 | G34: דנה שם טוב | I34: קידוש
A35: תורנות שבת | B35: שבת | C35: 0.45833333 | D35: ארוחת צהריים שבת | E35: הכנסת האוכל לתנור החימום: כתף בקר, אורז לבן, תפו"א ובטטה, אנטי פסטי, שווארמה טבעונית | F35: 2 | G35: איתמר אסנהיים, נעמי פונקלשטיין | I35: קידוש | J35: הגסטרונומים המסומנים 2 — שנה ב'
A36: תורנות שבת | B36: שבת | C36: 0.52083333 | D36: ארוחת צהריים שבת | E36: עריכת השולחן: הכנת סלט כרוב וסלט טחינה, והוצאת סלט חצילים, מטבוחה, סלטי קייטרינג (סלק אדום, ירקות מוחמצים, בטטה, כרוב במיונז, חומוס) וחלות | F36: 3 | G36: נדב טוקר, נגה שוהם, עפרי גזיאל | I36: ארוחת צהריים | J36: לוודא שהכל של שנה ב'
A37: תורנות שבת | B37: שבת | C37: 0.52083333 | D37: ארוחת צהריים שבת | E37: פריסת האוכל, כפות הגשה, צלחות וסכו"ם, וסידור שולחנות וכיסאות | F37: 2 | G37: איתמר אסנהיים, נעמי פונקלשטיין | I37: ארוחת צהריים
A38: תורנות שבת | B38: שבת | D38: ארוחת צהריים שבת | E38: פינוי השולחנות ושטיפת הגסטרונומים בסיום הארוחה | G38: איתמר אסנהיים, נעמי פונקלשטיין, נדב טוקר, נגה שוהם, עפרי גזיאל | I38: ארוחת צהריים
A39: תורנות שבת | B39: מוצאי שבת | E39: כולם בבית המדרש לחלוקת גזרות | I39: ניקיונות מוצ"ש
A124: «אנשים» = כמה צריך למשימה; ריק = כל הקבוצה. «שמות» מתמלא ע"י השיבוץ ואפשר לתקן ידנית. «מתכון» = מנה מ«מתכונים» (מודפסת על הפלייר רק עם --with-recipes). «עוגן» = האירוע בלו"ז שלידו המשימה תופיע בלו"ז הצל. הניקוד יושב ב«קבוצות».

Sheet קבוצות
A1: קבוצות העבודה השבת
A2: קבוצה | B2: שלב | C2: ניקוד | D2: אחראי/ת | E2: חניכים | F2: גודל | G2: משימות
A3: חלות | B3: הכנות שישי | C3: 3 | D3: איתמר אסנהיים | E3: איתמר אסנהיים, איתן כהן, נועם ישראל קומפאס, תמר פרימור, יהב לוי | F3: =IF(E3="","",LEN(E3)-LEN(SUBSTITUTE(E3,",",""))+1) | G3: =IF(A3="","",COUNTIF('משימות'!$D$3:$D$122,A3))
A4: עוגות שמרים | B4: הכנות שישי | C4: 3 | D4: חיים שמאי | E4: חיים שמאי, טליה קור, ניצן שטיין, של״ו רובינשטיין | F4: =IF(E4="","",LEN(E4)-LEN(SUBSTITUTE(E4,",",""))+1) | G4: =IF(A4="","",COUNTIF('משימות'!$D$3:$D$122,A4))
A5: מטבוחה | B5: הכנות שישי | C5: 3 | E5: הלל פינגולד, אביב רוזנטל, נגה חוה כהן, אורי טילינגר | F5: =IF(E5="","",LEN(E5)-LEN(SUBSTITUTE(E5,",",""))+1) | G5: =IF(A5="","",COUNTIF('משימות'!$D$3:$D$122,A5))
A6: עוגת דבש | B6: הכנות שישי | C6: 3 | E6: איתי בן מנחם, משה אוברשטיין | F6: =IF(E6="","",LEN(E6)-LEN(SUBSTITUTE(E6,",",""))+1) | G6: =IF(A6="","",COUNTIF('משימות'!$D$3:$D$122,A6))
A7: עוגיות שוקולד צ'יפס | B7: הכנות שישי | C7: 3 | E7: הילי אלפסי, נבו בלוך | F7: =IF(E7="","",LEN(E7)-LEN(SUBSTITUTE(E7,",",""))+1) | G7: =IF(A7="","",COUNTIF('משימות'!$D$3:$D$122,A7))
A8: בראוניז ללא גלוטן | B8: הכנות שישי | C8: 3 | E8: יובל רוזנברג, ארבל פרנקו | F8: =IF(E8="","",LEN(E8)-LEN(SUBSTITUTE(E8,",",""))+1) | G8: =IF(A8="","",COUNTIF('משימות'!$D$3:$D$122,A8))
A9: סלט חצילים | B9: הכנות שישי | C9: 3 | D9: יובל יצחק | E9: יובל יצחק, רוני כהן | F9: =IF(E9="","",LEN(E9)-LEN(SUBSTITUTE(E9,",",""))+1) | G9: =IF(A9="","",COUNTIF('משימות'!$D$3:$D$122,A9))
A10: ארוחת צהריים שישי | B10: הכנות שישי | C10: 3 | E10: איתי גוסטינר, שירה אדלה לוזון | F10: =IF(E10="","",LEN(E10)-LEN(SUBSTITUTE(E10,",",""))+1) | G10: =IF(A10="","",COUNTIF('משימות'!$D$3:$D$122,A10))
A11: בית מדרש | B11: תורנות שישי | C11: 3 | E11: אלרואי גרינברג, עומר יוסף גנון, תמר פרידמן, רועי צבי סרי, פרת פולס, ליבי בוכריס, ניצן גמלא, אלה מאיר, עשהאל ירושלמי, איתי רוס, עופר בביוף, איתי בן יהודה, הילה לביא, אנה עזריאל, ירדן בן שחר, שליו שישו | F11: =IF(E11="","",LEN(E11)-LEN(SUBSTITUTE(E11,",",""))+1) | G11: =IF(A11="","",COUNTIF('משימות'!$D$3:$D$122,A11))
A12: ארוחת ערב | B12: תורנות שבת | C12: 2 | D12: מישל דוד | E12: מישל דוד, איתן וינסטון, זואי כהן, שירה ספונוב, אורי אסף, יונתן לירז, אלה גוטליב, עמית שי אברהם | F12: =IF(E12="","",LEN(E12)-LEN(SUBSTITUTE(E12,",",""))+1) | G12: =IF(A12="","",COUNTIF('משימות'!$D$3:$D$122,A12))
A13: טיש | B13: תורנות שבת | C13: 1 | D13: מעיין רחל דינר | E13: מעיין רחל דינר, הדר עמדי, רגב שהם, אחיה נחמני, מעיין יוספי | F13: =IF(E13="","",LEN(E13)-LEN(SUBSTITUTE(E13,",",""))+1) | G13: =IF(A13="","",COUNTIF('משימות'!$D$3:$D$122,A13))
A14: קידוש | B14: תורנות שבת | C14: 1 | D14: עמרי קולטון | E14: עמרי קולטון, ליאור שימרלינג, יעל ברחד, אריאלה מרכוס, דנה שם טוב | F14: =IF(E14="","",LEN(E14)-LEN(SUBSTITUTE(E14,",",""))+1) | G14: =IF(A14="","",COUNTIF('משימות'!$D$3:$D$122,A14))
A15: ארוחת צהריים שבת | B15: תורנות שבת | C15: 2 | D15: איתמר אסנהיים | E15: איתמר אסנהיים, נעמי פונקלשטיין, נדב טוקר, נגה שוהם, עפרי גזיאל | F15: =IF(E15="","",LEN(E15)-LEN(SUBSTITUTE(E15,",",""))+1) | G15: =IF(A15="","",COUNTIF('משימות'!$D$3:$D$122,A15))
F16: =IF(E16="","",LEN(E16)-LEN(SUBSTITUTE(E16,",",""))+1) | G16: =IF(A16="","",COUNTIF('משימות'!$D$3:$D$122,A16))
F17: =IF(E17="","",LEN(E17)-LEN(SUBSTITUTE(E17,",",""))+1) | G17: =IF(A17="","",COUNTIF('משימות'!$D$3:$D$122,A17))
F18: =IF(E18="","",LEN(E18)-LEN(SUBSTITUTE(E18,",",""))+1) | G18: =IF(A18="","",COUNTIF('משימות'!$D$3:$D$122,A18))
F19: =IF(E19="","",LEN(E19)-LEN(SUBSTITUTE(E19,",",""))+1) | G19: =IF(A19="","",COUNTIF('משימות'!$D$3:$D$122,A19))
F20: =IF(E20="","",LEN(E20)-LEN(SUBSTITUTE(E20,",",""))+1) | G20: =IF(A20="","",COUNTIF('משימות'!$D$3:$D$122,A20))
F21: =IF(E21="","",LEN(E21)-LEN(SUBSTITUTE(E21,",",""))+1) | G21: =IF(A21="","",COUNTIF('משימות'!$D$3:$D$122,A21))
F22: =IF(E22="","",LEN(E22)-LEN(SUBSTITUTE(E22,",",""))+1) | G22: =IF(A22="","",COUNTIF('משימות'!$D$3:$D$122,A22))
F23: =IF(E23="","",LEN(E23)-LEN(SUBSTITUTE(E23,",",""))+1) | G23: =IF(A23="","",COUNTIF('משימות'!$D$3:$D$122,A23))
F24: =IF(E24="","",LEN(E24)-LEN(SUBSTITUTE(E24,",",""))+1) | G24: =IF(A24="","",COUNTIF('משימות'!$D$3:$D$122,A24))
F25: =IF(E25="","",LEN(E25)-LEN(SUBSTITUTE(E25,",",""))+1) | G25: =IF(A25="","",COUNTIF('משימות'!$D$3:$D$122,A25))
F26: =IF(E26="","",LEN(E26)-LEN(SUBSTITUTE(E26,",",""))+1) | G26: =IF(A26="","",COUNTIF('משימות'!$D$3:$D$122,A26))
F27: =IF(E27="","",LEN(E27)-LEN(SUBSTITUTE(E27,",",""))+1) | G27: =IF(A27="","",COUNTIF('משימות'!$D$3:$D$122,A27))
... F32: =IF(E32="","",LEN(E32)-LEN(SUBSTITUTE(E32,",",""))+1) | G32: =IF(A32="","",COUNTIF('משימות'!$D$3:$D$122,A32))

Sheet חניכים
A1: חניכים — מי נמצא, מי בתורנות, וכמה עומס
A2: שם | B2: תוכנית | C2: חבורה | D2: זמין/ה | E2: קבוצות השבת | F2: משימות השבת | G2: ניקוד השבת | H2: ניקוד מצטבר | I2: הערה
A3: ניתאי שלום | B3: מדרשה | C3: אבי | D3: כן | F3: =IF(A3="","",COUNTIF('משימות'!$G$3:$G$122,"*"&A3&"*")) | H3: =IF(A3="","",SUMIF('היסטוריה'!$B$3:$B$3002,A3,'היסטוריה'!$E$3:$E$3002))
A4: איתן וינסטון | B4: מדרשה | C4: אבי | D4: כן | E4: ארוחת ערב | F4: =IF(A4="","",COUNTIF('משימות'!$G$3:$G$122,"*"&A4&"*")) | G4: 2 | H4: =IF(A4="","",SUMIF('היסטוריה'!$B$3:$B$3002,A4,'היסטוריה'!$E$3:$E$3002))
A5: יובל יצחק | B5: מדרשה | C5: בניה | D5: כן | E5: סלט חצילים | F5: =IF(A5="","",COUNTIF('משימות'!$G$3:$G$122,"*"&A5&"*")) | G5: 3 | H5: =IF(A5="","",SUMIF('היסטוריה'!$B$3:$B$3002,A5,'היסטוריה'!$E$3:$E$3002))
A6: הילי אלפסי | B6: מדרשה | C6: הילה | D6: כן | E6: עוגיות שוקולד צ'יפס | F6: =IF(A6="","",COUNTIF('משימות'!$G$3:$G$122,"*"&A6&"*")) | G6: 3 | H6: =IF(A6="","",SUMIF('היסטוריה'!$B$3:$B$3002,A6,'היסטוריה'!$E$3:$E$3002))
A7: יהב לוי | B7: מדרשה | C7: יואב | D7: כן | E7: חלות | F7: =IF(A7="","",COUNTIF('משימות'!$G$3:$G$122,"*"&A7&"*")) | G7: 3 | H7: =IF(A7="","",SUMIF('היסטוריה'!$B$3:$B$3002,A7,'היסטוריה'!$E$3:$E$3002))
A8: שחר קרן | B8: מדרשה | C8: הילה | D8: כן | F8: =IF(A8="","",COUNTIF('משימות'!$G$3:$G$122,"*"&A8&"*")) | H8: =IF(A8="","",SUMIF('היסטוריה'!$B$3:$B$3002,A8,'היסטוריה'!$E$3:$E$3002))
A9: ירדן בן שחר | B9: מדרשה | C9: הילה | D9: כן | E9: בית מדרש | F9: =IF(A9="","",COUNTIF('משימות'!$G$3:$G$122,"*"&A9&"*")) | G9: 3 | H9: =IF(A9="","",SUMIF('היסטוריה'!$B$3:$B$3002,A9,'היסטוריה'!$E$3:$E$3002))
A10: אחיה נחמני | B10: מדרשה | C10: אבי | D10: כן | E10: טיש | F10: =IF(A10="","",COUNTIF('משימות'!$G$3:$G$122,"*"&A10&"*")) | G10: 1 | H10: =IF(A10="","",SUMIF('היסטוריה'!$B$3:$B$3002,A10,'היסטוריה'!$E$3:$E$3002))
A11: ניצן שטיין | B11: מדרשה | C11: יואב | D11: כן | E11: עוגות שמרים | F11: =IF(A11="","",COUNTIF('משימות'!$G$3:$G$122,"*"&A11&"*")) | G11: 3 | H11: =IF(A11="","",SUMIF('היסטוריה'!$B$3:$B$3002,A11,'היסטוריה'!$E$3:$E$3002))
A12: מעיין יוספי | B12: מדרשה | C12: יואב | D12: כן | E12: טיש | F12: =IF(A12="","",COUNTIF('משימות'!$G$3:$G$122,"*"&A12&"*")) | G12: 1 | H12: =IF(A12="","",SUMIF('היסטוריה'!$B$3:$B$3002,A12,'היסטוריה'!$E$3:$E$3002))
A13: יעל שם טוב | B13: מדרשה | F13: =IF(A13="","",COUNTIF('משימות'!$G$3:$G$122,"*"&A13&"*")) | H13: =IF(A13="","",SUMIF('היסטוריה'!$B$3:$B$3002,A13,'היסטוריה'!$E$3:$E$3002)) | I13: לא נוכח/ת
A14: עמית סיילס | B14: מדרשה | C14: תמר | D14: כן | F14: =IF(A14="","",COUNTIF('משימות'!$G$3:$G$122,"*"&A14&"*")) | H14: =IF(A14="","",SUMIF('היסטוריה'!$B$3:$B$3002,A14,'היסטוריה'!$E$3:$E$3002))
A15: אריאלה מרכוס | B15: מדרשה | C15: הילה | D15: כן | E15: קידוש | F15: =IF(A15="","",COUNTIF('משימות'!$G$3:$G$122,"*"&A15&"*")) | G15: 1 | H15: =IF(A15="","",SUMIF('היסטוריה'!$B$3:$B$3002,A15,'היסטוריה'!$E$3:$E$3002))
A16: משה אוברשטיין | B16: מדרשה | C16: תמר | D16: כן | E16: עוגת דבש | F16: =IF(A16="","",COUNTIF('משימות'!$G$3:$G$122,"*"&A16&"*")) | G16: 3 | H16: =IF(A16="","",SUMIF('היסטוריה'!$B$3:$B$3002,A16,'היסטוריה'!$E$3:$E$3002))
A17: אוריה תעשה | B17: מדרשה | C17: יואב | D17: כן | F17: =IF(A17="","",COUNTIF('משימות'!$G$3:$G$122,"*"&A17&"*")) | H17: =IF(A17="","",SUMIF('היסטוריה'!$B$3:$B$3002,A17,'היסטוריה'!$E$3:$E$3002))
A18: יונתן לירז | B18: מדרשה | C18: יואב | D18: כן | E18: ארוחת ערב | F18: =IF(A18="","",COUNTIF('משימות'!$G$3:$G$122,"*"&A18&"*")) | G18: 2 | H18: =IF(A18="","",SUMIF('היסטוריה'!$B$3:$B$3002,A18,'היסטוריה'!$E$3:$E$3002))
A19: פנחס אליהו גלוסקין | B19: מדרשה | F19: =IF(A19="","",COUNTIF('משימות'!$G$3:$G$122,"*"&A19&"*")) | H19: =IF(A19="","",SUMIF('היסטוריה'!$B$3:$B$3002,A19,'היסטוריה'!$E$3:$E$3002)) | I19: לא נוכח/ת
A20: נדב טוקר | B20: מדרשה | C20: בניה | D20: כן | E20: ארוחת צהריים שבת | F20: =IF(A20="","",COUNTIF('משימות'!$G$3:$G$122,"*"&A20&"*")) | G20: 2 | H20: =IF(A20="","",SUMIF('היסטוריה'!$B$3:$B$3002,A20,'היסטוריה'!$E$3:$E$3002))
A21: הדר עמדי | B21: מדרשה | C21: תמר | D21: כן | E21: טיש | F21: =IF(A21="","",COUNTIF('משימות'!$G$3:$G$122,"*"&A21&"*")) | G21: 1 | H21: =IF(A21="","",SUMIF('היסטוריה'!$B$3:$B$3002,A21,'היסטוריה'!$E$3:$E$3002))
A22: יואב אוחנה | B22: מדרשה | C22: הילה | D22: כן | F22: =IF(A22="","",COUNTIF('משימות'!$G$3:$G$122,"*"&A22&"*")) | H22: =IF(A22="","",SUMIF('היסטוריה'!$B$3:$B$3002,A22,'היסטוריה'!$E$3:$E$3002))
A23: איתי בן יהודה | B23: מדרשה | C23: תמר | D23: כן | E23: בית מדרש | F23: =IF(A23="","",COUNTIF('משימות'!$G$3:$G$122,"*"&A23&"*")) | G23: 3 | H23: =IF(A23="","",SUMIF('היסטוריה'!$B$3:$B$3002,A23,'היסטוריה'!$E$3:$E$3002))
A24: עופר בביוף | B24: מדרשה | C24: יואב | D24: כן | E24: בית מדרש | F24: =IF(A24="","",COUNTIF('משימות'!$G$3:$G$122,"*"&A24&"*")) | G24: 3 | H24: =IF(A24="","",SUMIF('היסטוריה'!$B$3:$B$3002,A24,'היסטוריה'!$E$3:$E$3002))
A25: הילה עזרא | B25: מדרשה | C25: הילה | D25: כן | F25: =IF(A25="","",COUNTIF('משימות'!$G$3:$G$122,"*"&A25&"*")) | H25: =IF(A25="","",SUMIF('היסטוריה'!$B$3:$B$3002,A25,'היסטוריה'!$E$3:$E$3002))
A26: בניה מעוז | B26: מדרשה | F26: =IF(A26="","",COUNTIF('משימות'!$G$3:$G$122,"*"&A26&"*")) | H26: =IF(A26="","",SUMIF('היסטוריה'!$B$3:$B$3002,A26,'היסטוריה'!$E$3:$E$3002)) | I26: לא נוכח/ת
A27: שחר מרקוביץ' גליק | B27: מדרשה | F27: =IF(A27="","",COUNTIF('משימות'!$G$3:$G$122,"*"&A27&"*")) | H27: =IF(A27="","",SUMIF('היסטוריה'!$B$3:$B$3002,A27,'היסטוריה'!$E$3:$E$3002)) | I27: לא נוכח/ת
A28: שליו שישו | B28: מדרשה | C28: תמר | D28: כן | E28: בית מדרש | F28: =IF(A28="","",COUNTIF('משימות'!$G$3:$G$122,"*"&A28&"*")) | G28: 3 | H28: =IF(A28="","",SUMIF('היסטוריה'!$B$3:$B$3002,A28,'היסטוריה'!$E$3:$E$3002))
A29: חיים שמאי | B29: מדרשה | C29: הילה | D29: כן | E29: עוגות שמרים | F29: =IF(A29="","",COUNTIF('משימות'!$G$3:$G$122,"*"&A29&"*")) | G29: 3 | H29: =IF(A29="","",SUMIF('היסטוריה'!$B$3:$B$3002,A29,'היסטוריה'!$E$3:$E$3002))
A30: אנה עזריאל | B30: מדרשה | C30: יואב | D30: כן | E30: בית מדרש | F30: =IF(A30="","",COUNTIF('משימות'!$G$3:$G$122,"*"&A30&"*")) | G30: 3 | H30: =IF(A30="","",SUMIF('היסטוריה'!$B$3:$B$3002,A30,'היסטוריה'!$E$3:$E$3002))
A31: אלרואי גרינברג | B31: מדרשה | C31: אבי | D31: כן | E31: בית מדרש | F31: =IF(A31="","",COUNTIF('משימות'!$G$3:$G$122,"*"&A31&"*")) | G31: 3 | H31: =IF(A31="","",SUMIF('היסטוריה'!$B$3:$B$3002,A31,'היסטוריה'!$E$3:$E$3002))
A32: אלה גוטליב | B32: מדרשה | C32: תמר | D32: כן | E32: ארוחת ערב | F32: =IF(A32="","",COUNTIF('משימות'!$G$3:$G$122,"*"&A32&"*")) | G32: 2 | H32: =IF(A32="","",SUMIF('היסטוריה'!$B$3:$B$3002,A32,'היסטוריה'!$E$3:$E$3002))
A33: רותם דרור | B33: מדרשה | C33: אבי | D33: כן | F33: =IF(A33="","",COUNTIF('משימות'!$G$3:$G$122,"*"&A33&"*")) | H33: =IF(A33="","",SUMIF('היסטוריה'!$B$3:$B$3002,A33,'היסטוריה'!$E$3:$E$3002))
A34: עומר יוסף גנון | B34: מדרשה | C34: בניה | D34: כן | E34: בית מדרש | F34: =IF(A34="","",COUNTIF('משימות'!$G$3:$G$122,"*"&A34&"*")) | G34: 3 | H34: =IF(A34="","",SUMIF('היסטוריה'!$B$3:$B$3002,A34,'היסטוריה'!$E$3:$E$3002))
A35: סהר שירון | B35: מדרשה | C35: הילה | D35: כן | F35: =IF(A35="","",COUNTIF('משימות'!$G$3:$G$122,"*"&A35&"*")) | H35: =IF(A35="","",SUMIF('היסטוריה'!$B$3:$B$3002,A35,'היסטוריה'!$E$3:$E$3002))
A36: שירה ספונוב | B36: מדרשה | C36: הילה | D36: כן | E36: ארוחת ערב | F36: =IF(A36="","",COUNTIF('משימות'!$G$3:$G$122,"*"&A36&"*")) | G36: 2 | H36: =IF(A36="","",SUMIF('היסטוריה'!$B$3:$B$3002,A36,'היסטוריה'!$E$3:$E$3002))
A37: הלל פינגולד | B37: מדרשה | C37: הילה | D37: כן | E37: מטבוחה | F37: =IF(A37="","",COUNTIF('משימות'!$G$3:$G$122,"*"&A37&"*")) | G37: 3 | H37: =IF(A37="","",SUMIF('היסטוריה'!$B$3:$B$3002,A37,'היסטוריה'!$E$3:$E$3002))
A38: מישל דוד | B38: מדרשה | C38: בניה | D38: כן | E38: ארוחת ערב | F38: =IF(A38="","",COUNTIF('משימות'!$G$3:$G$122,"*"&A38&"*")) | G38: 2 | H38: =IF(A38="","",SUMIF('היסטוריה'!$B$3:$B$3002,A38,'היסטוריה'!$E$3:$E$3002))
A39: מעיין רחל דינר | B39: מדרשה | C39: בניה | D39: כן | E39: טיש | F39: =IF(A39="","",COUNTIF('משימות'!$G$3:$G$122,"*"&A39&"*")) | G39: 1 | H39: =IF(A39="","",SUMIF('היסטוריה'!$B$3:$B$3002,A39,'היסטוריה'!$E$3:$E$3002))
A40: עמרי קולטון | B40: מדרשה | C40: בניה | D40: כן | E40: קידוש | F40: =IF(A40="","",COUNTIF('משימות'!$G$3:$G$122,"*"&A40&"*")) | G40: 1 | H40: =IF(A40="","",SUMIF('היסטוריה'!$B$3:$B$3002,A40,'היסטוריה'!$E$3:$E$3002))
...

Sheet היסטוריה
A1: היסטוריית תורנויות — רשומה לכל תורנות של כל חניך
A2: תאריך | B2: שם | C2: שלב | D2: קבוצה | E2: ניקוד
A3: 46269 | B3: אוריה תעשה | C3: הכנות שישי | D3: ארוחת צהריים שישי | E3: 3
A4: 46269 | B4: ינון לוי | C4: הכנות שישי | D4: ארוחת צהריים שישי | E4: 3
A5: 46269 | B5: ליעם גבע | C5: הכנות שישי | D5: ארוחת צהריים שישי | E5: 3
A6: 46269 | B6: שי- לי וולגמוט | C6: הכנות שישי | D6: ארוחת צהריים שישי | E6: 3
A7: 46269 | B7: אביה וייל | C7: הכנות שישי | D7: עוגות · צוות יותם | E7: 3
A8: 46269 | B8: יואב אוחנה | C8: הכנות שישי | D8: עוגות · צוות יותם | E8: 3
A9: 46269 | B9: יותם ספיר | C9: הכנות שישי | D9: עוגות · צוות יותם | E9: 3
A10: 46269 | B10: כליל בלאוקופף | C10: הכנות שישי | D10: עוגות · צוות סהר | E10: 3
A11: 46269 | B11: נוה גריינר | C11: הכנות שישי | D11: עוגות · צוות סהר | E11: 3
A12: 46269 | B12: סהר שירון | C12: הכנות שישי | D12: עוגות · צוות סהר | E12: 3
A13: 46269 | B13: הילה עזרא | C13: הכנות שישי | D13: עוגות · צוות רותם | E13: 3
A14: 46269 | B14: יאר אלפסי | C14: הכנות שישי | D14: עוגות · צוות רותם | E14: 3
... A99: 46283 | B99: תמר פרידמן | C99: תורנות שישי | D99: בית מדרש | E99: 3

Sheet מתכונים
A1: מתכונים — עוגות, סלטים, מטבוחה וארוחת צהריים שישי
A2: קטגוריה | B2: מנה | C2: כמות | D2: מרכיבים | E2: הוראות | F2: הערה
A3: מאפים | B3: חלות | C3: 10 ק"ג קמח | D3: 10 ק"ג קמח 200 גרם שמרים יבשים 1 ק"ג סוכר 1.2–1.33 ליטר שמן כ-5 ליטר מים פושרים כ-150 גרם מלח (כ-6 כפות) ביצים ושומשום להברשה | E3: בקערות גדולות מאוד שופכים את הקמח, יוצרים גומות ושמים את השמרים והסוכר. מוסיפים בהדרגה כ-4.5 ליטר מים פושרים ומתחילים ללוש. מוסיפים את השמן וממשיכים ללוש. לקראת סוף הלישה מוסיפים את המלח ואת יתרת המים במידת הצורך, עד לבצק רך, גמיש ולא דביק (כ-10–12 דקות). משמנים מעט את פני הבצק, מכסים ומתפיחים עד להכפלת הנפח (60–90 דקות). מורידים אוויר, מחלקים לכדורים שווים, יוצרים רצועות וקולעים חלות. מניחים על תבניות עם נייר אפייה, מכסים ומתפיחים שוב 30–40 דקות. מברישים בביצה טרופה, מפזרים שומשום ואופים ב-180 מעלות 25–30 דקות, עד להזהבה עמוקה גם בתחתית. | F3: שתי התפחות — להתחיל מוקדם
A4: עוגות | B4: עוגות שמרים (קראנץ' קינמון ושוקולד) | C4: 6–8 קראנצ'ים | D4: לבצק: 3 ק"ג קמח 50 גרם שמרים יבשים 3 שקיות אבקת אפייה 400 גרם סוכר (כ-2 כוסות) 12 ביצים 500 מ"ל שמן תמצית וניל כ-700–900 מ"ל מים פושרים (לפי ספיגת הבצק) למילוי: 1.6 ק"ג סוכר 300 גרם קקאו 6 כפות קינמון 500 מ"ל שמן (למריחה וחיבור המילוי) | E4: הבצק: מערבבים קמח, שמרים, אבקת אפייה ו-400 גרם סוכר. מוסיפים ביצים, תמצית וניל, שמן ומים בהדרגה. לשים כ-10 דקות לבצק רך, חלק וגמיש. מתפיחים שעה עד שעה וחצי להכפלת הנפח. המילוי: מערבבים את הסוכר שנותר, הקקאו והקינמון לתערובת אחידה. מחלקים את הבצק ל-6–8 כדורים שווים ומרדדים כל אחד למלבן דק. מברישים בשכבת שמן נדיבה ומפזרים שכבה אחידה ונדיבה מתערובת הסוכר-קקאו-קינמון. מגלגלים לרולדה מהודקת, חוצים לאורכה לשתי רצועות וקולעים לצמת בורג. מניחים בתבניות, מתפיחים 30 דקות נוספות, ואופים ב-175 מעלות 25–30 דקות עד להשחמה יפה.
A5: בישול | B5: מטבוחה | C5: 100 עגבניות | D5: 100 עגבניות אדומות ובשלות (חלוטות, מקולפות וקצוצות) 1 ק"ג עגבניות שרי (קצוצות, אם משתמשים) 3–4 ק"ג פלפלים אדומים (קוביות קטנות או קלויים ומקולפים) 6 פלפלים ירוקים חריפים (קצוצים דק) 22 שיני שום פרוסות או כתושות 1 ליטר שמן (עדיף זית) מלח גס לפי הטעם 4–5 כפות פפריקה מתוקה בשמן מעט פפריקה חריפה | E5: בסיר גדול ורחב מחממים חצי מכמות השמן (500 מ"ל) על אש בינונית. מוסיפים שום ופלפלים חריפים ומטגנים כדקה (להיזהר לא לשרוף את השום). מוסיפים את הפלפלים האדומים ומבשלים תוך ערבוב כ-15 דקות עד שהם מתרככים. מוסיפים את העגבניות הקצוצות (והשרי). מביאים לרתיחה, מנמיכים לאש נמוכה ומבשלים ללא מכסה עד שהנוזלים מצטמצמים כמעט לחלוטין (כשעתיים-שלוש). כשהעגבניות התפרקו והנוזלים התאדו, מוסיפים את יתרת השמן (500 מ"ל), מלח ופפריקה. ממשיכים לבשל על אש קטנה מאוד עוד כשעה, תוך ערבוב תכוף בתחתית, עד למרקם ריבתי מבריק והשמן נפרד וצף בצדדים. | F5: בישול ארוך — כ-4 שעות בסך הכל
A6: עוגות | B6: עוגת דבש | C6: 10–12 תבניות אינגליש קייק | D6: 30 ביצים 1.5 ק"ג סוכר (7.5 כוסות) 1.8 ליטר שמן (7.5 כוסות) 7.5 כוסות דבש 10 כפיות גדושות קפה נמס (מומסות ב-3 כוסות מים רותחים) 2.8 ק"ג קמח (20 כוסות) 10 כפיות אבקת אפייה (כ-3 שקיות) 5 כפיות סודה לשתייה 5 כפיות קינמון | E6: בקערת ערבוב ענקית טורפים היטב את הביצים עם הסוכר עד לתערובת בהירה ומעט תפוחה. מוסיפים בהדרגה את השמן, הדבש והקפה המומס (לוודא שאינו רותח מדי שלא יבשל את הביצים) וטורפים עד לאיחוד. בקערה נפרדת מערבבים את היבשים: קמח, אבקת אפייה, סודה לשתייה וקינמון. מוסיפים את היבשים אל הרטובים וטורפים רק עד לבלילה חלקה ללא גושים (ערבוב יתר יפגע באווריריות). מחלקים לתבניות אינגליש משומנות (עד 2/3 מגובה התבנית) ואופים ב-165 מעלות 35–45 דקות, עד שקיסם במרכז יוצא יבש עם פירורים לחים.
A7: עוגות | B7: עוגיות שוקולד צ'יפס | C7: כ-1.2 ק"ג קמח | D7: 1.2 ק"ג קמח 1 שקית אבקת אפייה 1 כפית סודה לשתייה 675 גרם חמאה קרה (חתוכה לקוביות) 540 גרם סוכר חום כהה 300 גרם סוכר לבן 360 גרם ביצים (כ-6–7 ביצים) 1 כף תמצית וניל קורט מלח 990 גרם שוקולד צ'יפס | E7: מעבדים בקערה גדולה (או במיקסר עם וו גיטרה) את החמאה הקרה עם שני סוגי הסוכר עד לתערובת פירורית ואחידה. מוסיפים את הביצים בהדרגה ואת תמצית הווניל, ומערבבים עד להטמעה. מוסיפים קמח, אבקת אפייה, סודה לשתייה וקורט מלח, ומערבבים רק עד שמתקבל בצק אחיד (לא ללוש יותר מדי). מקפלים פנימה את השוקולד צ'יפס. מומלץ להכניס למקרר ל-30 דקות לייצוב. מכדררים כדורים בגודל כדור פינג-פונג, מניחים על תבנית מרופדת עם מרווחים נדיבים, ואופים ב-175 מעלות 10–12 דקות, עד שהשוליים זהובים והמרכז עדיין רך.
A8: עוגות | B8: בראוניז ללא גלוטן | C8: כ-600 גרם שוקולד | D8: 600 גרם שוקולד מריר 660 מ"ל שמן (כ-2.75 כוסות) 3.75 כוסות סוכר 15 ביצים שלמות 3 חבילות אינסטנט פודינג שוקולד או וניל ללא גלוטן | E8: ממיסים את השוקולד המריר יחד עם השמן בקערה גדולה (במיקרוגל בפולסים של 30 שניות או מעל סיר מים חמים) עד לתערובת חלקה ומבריקה. בקערה נפרדת טורפים היטב את הביצים יחד עם הסוכר במטרפה ידנית. יוצקים את תערובת השוקולד והשמן אל הביצים תוך כדי טריפה מתמדת. מוסיפים את אבקת האינסטנט פודינג וטורפים רק עד לבלילה אחידה ללא גושים. יוצקים לתבניות מרופדות בנייר אפייה ואופים ב-175 מעלות 25–30 דקות. מוכן כשהשוליים יציבים והמרכז מעט רוטט ופאדג'י. מצננים לחלוטין לפני חיתוך. | F8: ללא גלוטן — לוודא שכל המצרכים מסומנים
A9: סלטים | B9: סלט חצילים קלויים | C9: 10 חצילים | D9: 10 חצילים שלמים 5–7 שיני שום כתושות מיץ מ-4–5 לימונים 1 כוס שמן זית (200–250 מ"ל) מלח לפי הטעם לחציל בטחינה: 1–1.5 חבילות טחינה גולמית ומעט מים | E9: דוקרים כל חציל במזלג ב-2–3 מקומות וקולים על להבת גז גלויה, גריל, או בתנור על חום מקסימלי (גריל עליון) 30–40 דקות, עד שהקליפה חרוכה לחלוטין והבשר רך מאוד. מעבירים למסננת לכ-15 דקות לצינון ולהגרת נוזלים מרירים. חורצים לאורך, גורפים את בשר החציל בכף לקערה, וקוצצים גס בסכין (לא לטחון בבלנדר). מוסיפים שום כתוש, מיץ לימון, שמן זית ומלח ומערבבים היטב במזלג.
A10: סלטים | B10: סלט כרוב מרענן | C10: 4 ראשי כרוב (מלאה) | D10: 4 ראשי כרוב (קצוצים לרצועות דקות) מיץ מ-4–5 לימונים 1.25 כוסות שמן זית (250–300 מ"ל) כ-2 כפות מלח (לפי הטעם) אופציונלי: כפית שטוחה סוכר / פלפל שחור / שמיר קצוץ | E10: חותכים את הכרוב לרצועות דקות ושמים בקערה גדולה מאוד. בצנצנת או קערה קטנה טורפים יחד שמן זית, מיץ לימון ומלח עד לאיחוד. יוצקים את הרוטב מעל הכרוב ומעסים את הכרוב בידיים דקה-שתיים (העיסוי מרכך את הכרוב ומחדיר את הטעמים). מניחים בצד כ-20 דקות לפני ההגשה, טועמים ומתקנים תיבול. | F10: מכינים חצי כמות (2 כרובים) לכל ארוחה, סמוך להגשה
A11: סלטים | B11: סלט טחינה ביתית | C11: 3–4 חבילות טחינה (מלאה) | D11: 3–4 חבילות טחינה גולמית (או 2.5 אם הוספתם לחציל) מיץ מ-5–6 לימונים 4–6 שיני שום כתושות מים קרים מאוד (בערך נפח הטחינה — להוסיף בהדרגה) מלח לפי הטעם 2–3 כפות שמן זית לזילוף | E11: יוצקים את הטחינה הגולמית לקערה גדולה. מוסיפים מיץ לימון, שום כתוש ומלח, ומתחילים לערבב במטרפה (התערובת תהפוך תחילה סמיכה מאוד וגושית — זה נורמלי). מוסיפים מים קרים בהדרגה תוך טריפה נמרצת, עד למרקם הרצוי (טחינה מסמיכה בקירור, לא להשאיר סמיכה מדי). טועמים ומאזנים מליחות וחמיצות. מעבירים לקערות הגשה ומזלפים מעט שמן זית מעל. | F11: מכינים חצי כמות לכל ארוחה, סמוך להגשה
A84: שם המנה (עמודה B) הוא מה שבוחרים בעמודת «מתכון» ב«משימות» — והמתכון מודפס על הפלייר של הקבוצה. מרכיבים והוראות: שורה לכל פריט (Alt+Enter לשורה חדשה בתא).

Sheet קייטרינג
A1: קייטרינג — מה מגיע לכל ארוחה
A2: ארוחה | B2: מנה | C2: כמות | D2: הערה

Sheet זמנים
A1: לוח שבתות — זמני ירושלים
A2: תאריך | B2: פרשה | C2: כניסת שבת | D2: צאת שבת | E2: ניתן לעריכה
A3: 46269 | B3: נצבים, וילך | C3: 0.76388889 | D3: 0.81875 | E3: הזמנים מחושבים לירושלים (כניסה 40 דק' לפני השקיעה, צאה 40 דק' אחריה). אם הלוח שלך אומר אחרת — תקנו את השורה.
A4: 46276 | B4: ראש השנה | C4: 0.75763889 | D4: 0.8125
A5: 46283 | B5: האזינו | C5: 0.75138889 | D5: 0.80555556
A6: 46290 | B6: סוכות | C6: 0.74513889 | D6: 0.79930556
A7: 46297 | B7: שמיני עצרת | C7: 0.73888889 | D7: 0.79305556
A8: 46304 | B8: בראשית | C8: 0.73263889 | D8: 0.7875
A9: 46311 | B9: נח | C9: 0.72638889 | D9: 0.78125
A10: 46318 | B10: לך לך | C10: 0.72152778 | D10: 0.77638889
A11: 46325 | B11: וירא | C11: 0.675 | D11: 0.72986111
A12: 46332 | B12: חיי שרה | C12: 0.67083333 | D12: 0.72569444
A13: 46339 | B13: תולדות | C13: 0.66736111 | D13: 0.72291667
A14: 46346 | B14: ויצא | C14: 0.66527778 | D14: 0.72013889
A15: 46353 | B15: וישלח | C15: 0.66388889 | D15: 0.71875
... A54: 46626 | B54: ראה | C54: 0.77083333 | D54: 0.82569444
